# numpyがおかしかった話。
ここ最近pipの「~が入っていない」が頻発していた。
たとえばこれ
~~~
(base) C:\Users\rinta>pipdeptree
Traceback (most recent call last):
  File "C:\Users\rinta\anaconda3\lib\site-packages\pip\_vendor\pkg_resources\__init__.py", line 3021, in _dep_map
    return self.__dep_map
  File "C:\Users\rinta\anaconda3\lib\site-packages\pip\_vendor\pkg_resources\__init__.py", line 2815, in __getattr__
    raise AttributeError(attr)
AttributeError: _DistInfoDistribution__dep_map

During handling of the above exception, another exception occurred:

Traceback (most recent call last):
  File "C:\Users\rinta\anaconda3\lib\site-packages\pip\_vendor\pkg_resources\__init__.py", line 3012, in _parsed_pkg_info
    return self._pkg_info
  File "C:\Users\rinta\anaconda3\lib\site-packages\pip\_vendor\pkg_resources\__init__.py", line 2815, in __getattr__
    raise AttributeError(attr)
AttributeError: _pkg_info

During handling of the above exception, another exception occurred:

Traceback (most recent call last):
  File "C:\Users\rinta\anaconda3\lib\runpy.py", line 194, in _run_module_as_main
    return _run_code(code, main_globals, None,
  File "C:\Users\rinta\anaconda3\lib\runpy.py", line 87, in _run_code
    exec(code, run_globals)
  File "C:\Users\rinta\anaconda3\Scripts\pipdeptree.exe\__main__.py", line 7, in <module>
  File "C:\Users\rinta\anaconda3\lib\site-packages\pipdeptree\__init__.py", line 962, in main
    tree = PackageDAG.from_pkgs(pkgs)
  File "C:\Users\rinta\anaconda3\lib\site-packages\pipdeptree\__init__.py", line 275, in from_pkgs
    m = {p: [ReqPackage(r, idx.get(r.key)) for r in p.requires()] for p in pkgs}
  File "C:\Users\rinta\anaconda3\lib\site-packages\pipdeptree\__init__.py", line 275, in <dictcomp>
    m = {p: [ReqPackage(r, idx.get(r.key)) for r in p.requires()] for p in pkgs}
  File "C:\Users\rinta\anaconda3\lib\site-packages\pip\_vendor\pkg_resources\__init__.py", line 2736, in requires
    dm = self._dep_map
  File "C:\Users\rinta\anaconda3\lib\site-packages\pip\_vendor\pkg_resources\__init__.py", line 3023, in _dep_map
    self.__dep_map = self._compute_dependencies()
  File "C:\Users\rinta\anaconda3\lib\site-packages\pip\_vendor\pkg_resources\__init__.py", line 3032, in _compute_dependencies
    for req in self._parsed_pkg_info.get_all('Requires-Dist') or []:
  File "C:\Users\rinta\anaconda3\lib\site-packages\pip\_vendor\pkg_resources\__init__.py", line 3014, in _parsed_pkg_info
    metadata = self.get_metadata(self.PKG_INFO)
  File "C:\Users\rinta\anaconda3\lib\site-packages\pip\_vendor\pkg_resources\__init__.py", line 1420, in get_metadata
    value = self._get(path)
  File "C:\Users\rinta\anaconda3\lib\site-packages\pip\_vendor\pkg_resources\__init__.py", line 1616, in _get
    with open(path, 'rb') as stream:
FileNotFoundError: [Errno 2] No such file or directory: 'c:\\users\\rinta\\anaconda3\\lib\\site-packages\\numpy-1.23.5.dist-info\\METADATA'
 ~~~
 
こんなのが最近続いていた  
最初はバージョンの問題かなあと思っていたのだが、いくらupdateしてもうまくいかない  
チャットgptに聞くと  
「reinstallしろ」  
とでてくるが、anacondaで依存関係が絡まっているとおちおちreinstallもできない  
そこで、一度バージョンを落としてみたところ、もどしたら正常に動作するようになった  
なんだったのか…  
ちなみにバージョン管理に便利らしいのが、pipdeptree  
pipでインストールできる  
実行は  
$pipdeptree  
とすればいい。とってもeasy、  
